### 异常

**异常定义：**
导致程序的正常流程被中断的事件，叫做异常

```java
import java.io.File;
import java.io.FileInputStream;
  
public class TestException {
    public static void main(String[] args) {          
        File f= new File("d:/LOL.exe");
        //试图打开文件LOL.exe，会抛出FileNotFoundException，如果不处理该异常，就会有编译错误,这里就没有处理
        new FileInputStream(f);         
    }
}
```

#### 处理异常

异常处理常见手段： `try catch` ; `finally throws`

##### try catch

1.将可能抛出`FileNotFoundException `**文件不存在异常**的代码放在try里
2.如果文件存在，就会顺序往下执行，并且不执行catch块中的代码

3.如果文件不存在，`try `里的代码会立即终止，程序流程会运行到对应的catch块中

4.`e.printStackTrace(); `会打印出方法的调用痕迹，如此例，会打印出异常开始于`TestException`的第几行，这样就便于定位和分析到底哪里出了异常

```java
import java.io.File;
import java.io.FileInputStream;
import java.io.FileNotFoundException;
 
public class TestException {
    public static void main(String[] args) {
        File f= new File("d:/LOL.exe");
      
        try{
            System.out.println("试图打开 d:/LOL.exe");
            new FileInputStream(f);
            System.out.println("成功打开");
        }
        catch(FileNotFoundException e){
            System.out.println("d:/LOL.exe不存在");
            e.printStackTrace();
        }        
    }
}
```

##### 使用异常的父类 catch

`FileNotFoundException`是`Exception`的子类，使用`Exception`也可以`catch`住`FileNotFoundException`

```java
import java.io.File;
import java.io.FileInputStream;
import java.io.FileNotFoundException;
  
public class TestException {
    public static void main(String[] args) {
        File f= new File("d:/LOL.exe");
        try{
            System.out.println("试图打开 d:/LOL.exe");
            new FileInputStream(f);
            System.out.println("成功打开");
        }
        catch(Exception e){ // 使用的是FileNotFoundExceptio的父类Exception
            System.out.println("d:/LOL.exe不存在");
            e.printStackTrace();
        }         
    }
}
```

##### 多异常1

有的时候一段代码会抛出多种异常，比如

```java
new FileInputStream(f);

Date d = sdf.parse("2016-06-03");
```

这段代码，会抛出文件不存在异常 `FileNotFoundException` 和 解析异常`ParseException`
解决办法之一是分别进行`catch`

```java
catch (FileNotFoundException e) {
    System.out.println("d:/LOL.exe不存在");
    e.printStackTrace();
} catch (ParseException e) {
    System.out.println("日期格式解析错误");
    e.printStackTrace();
}
```

##### 多异常2

另一个种办法是把多个异常，放在一个`catch`里统一捕捉

`catch (FileNotFoundException | ParseException e) {`
这种方式从 JDK7开始支持，好处是捕捉的代码**更紧凑**，不足之处是，一旦发生异常，**不能确定到底是哪种异常**，需要通过`instanceof `进行判断具体的异常类型(它的作用是判断其左边对象是否为其右边类的实例，返回`boolean`类型的数据，运算优先级低于`!`。)

 ```JAVA
if (e instanceof FileNotFoundException)
	System.out.println("d:/LOL.exe不存在");
if (e instanceof ParseException)
	System.out.println("日期格式解析错误");
 ```

```java
if(!mycar instanceof Car)
```

这段代码永远会得到false（`!mycar`将在`instanceof`之前被处理，所以你总是在验证一个布尔值是否是Car的一个实例）。

##### finally

无论是否出现异常，finally中的代码都会被执行

```java
public class TestException {
    public static void main(String[] args) {    
        File f= new File("d:/LOL.exe");
        try{
            System.out.println("试图打开 d:/LOL.exe");
            new FileInputStream(f);
            System.out.println("成功打开");
        }
        catch(FileNotFoundException e){
            System.out.println("d:/LOL.exe不存在");
            e.printStackTrace();
        }
        finally{
            System.out.println("无论文件是否存在， 都会执行的代码");
        }
    }
}
```

##### throws

考虑如下情况：
主方法调用`method1`
`method1`调用`method2`
`method2`中打开文件

`method2`中需要进行异常处理
但是`method2`**不打算处理**，而是把这个异常通过**throws** **抛出去**
那么`method1`就会**接到该异常**。 处理办法也是两种，要么是`try catch`处理掉，要么也是**抛出去**。
`method1`选择本地`try catch`住 一旦`try catch`住了，就相当于把这个异常消化掉了，主方法在调用`method1`的时候，就不需要进行异常处理了

```java
import java.io.File;
import java.io.FileInputStream;
import java.io.FileNotFoundException;
 
public class TestException {
    public static void main(String[] args) {
        method1();
    }
    private static void method1() {
        try {
            method2();
        } catch (FileNotFoundException e) {
            // TODO Auto-generated catch block
            e.printStackTrace();
        }
    }
    private static void method2() throws FileNotFoundException {
        File f = new File("d:/LOL.exe");
 
        System.out.println("试图打开 d:/LOL.exe");
        new FileInputStream(f);
        System.out.println("成功打开");
    }
}
```

##### throw和throws的区别

throws与throw这两个关键字接近，不过意义不一样，有如下区别：

1. `throws` 出现在方法声明上，而`throw`通常都出现在方法体内。
2. `throws` 表示出现异常的一种可能性，并不一定会发生这些异常；`throw`则是抛出了异常，执行`throw`则一定抛出了某个异常对象。

##### finally一定会执行

假设有一个方法` public int method()，` 会返回一个整数
在这个方法中有`try catch `和 `finally.`
`try `里返回 1
`catch `里 返回 2
`finally `里 返回3
那么，这个方法到底返回多少？

**答**

最后结果是取finally的返回值3.

无论try代码块中是否有异常，finally里的代码都会执行 当try和catch代码块中有return语句时，finally仍然会执行 如果try...catch...finally都有return语句，则等待try catch执行完之后，跳过try catch里的return语句只执行finally中的return语句 如果仅仅是try...catch里有return语句，那么在执行return语句之前会先执行finally代码块里的内容



#### 异常分类

异常分类： **可查异常**，**运行时异常**和**错误**3种
其中，运行时异常和错误又叫非可查异常

![](https://i.loli.net/2020/11/21/UzPhZqyktmcFlYM.png)

##### 可查异常

可查异常：`CheckedException`
可查异常即**必须进行处理的异常**，要么try catch住,要么往外抛，谁调用，谁处理，比如 `FileNotFoundException`
如果不处理，编译器就不让你通过

##### 运行时异常

运行时异常`RuntimeException`指： **不是必须进行try catch的异常**
**常见运行时异常:**
除数不能为0异常:`ArithmeticException`
下标越界异常:`ArrayIndexOutOfBoundsException`
空指针异常:`NullPointerException`
在编写代码的时候，依然可以使用`try catch throws`进行处理，与可查异常不同之处在于，**即便不进行try catch，也不会有编译错误**

Java之所以会设计运行时异常的原因之一，是因为下标越界，空指针这些运行时异常**太过于普遍**，如果都需要进行捕捉，代码的可读性就会变得很糟糕。

##### 错误

错误`Error`，指的是**系统级别的异常**，通常是内存用光了
在**默认设置下**，一般java程序启动的时候，最大可以使用16m的内存
如例不停的给`StringBuffer`追加字符，很快就把内存使用光了。抛出`OutOfMemoryError`
与运行时异常一样，错误也是不要求强制捕捉的



#### Throwable

`Throwable`是类，`Exception`和`Error`都继承了该类
所以在捕捉的时候，也可以使用`Throwable`进行捕捉
如图： 异常分**Error**和**Exception**
`Exception`里又分**运行时异常**和**可查异常**。

![Throwable](https://i.loli.net/2020/11/21/cSAOhEwyromHIj1.png)

```java
import java.io.File;
import java.io.FileInputStream;
 
public class TestException {
    public static void main(String[] args) {
        File f = new File("d:/LOL.exe");
        try {
            new FileInputStream(f);
            //使用Throwable进行异常捕捉
        } catch (Throwable t) {  //使用Throwable进行异常捕捉
            // TODO Auto-generated catch block
            t.printStackTrace();
        }
    }
}
```

##### 问题

在方法声明上，可以抛出指定的异常，比如`FileNotFoundException`

那么能否抛出`Throwable`这个类？

这个方法的调用者又该如何处理？

**答**

抛出`Throwable`类是可以的，可以抛出Throwable这个类，但catch的时候必须也是Throwable类型

```java
package exception;
 
import java.io.FileNotFoundException;
 
public class demo1 {
    public static void main(String[] args){
        try {
            throwCheck(2);
        }catch (Throwable e){
            e.printStackTrace();
        }
        throwRun(-3);
 
    }
    public static void throwCheck(int a) throws Throwable{
        if(a > 0){
            throw new Exception("a");
        }
    }
    public static void throwRun(int a){
        if(a > -1){
            throw new RuntimeException("a > -1");
        }
    }
}
```

#### 自定义异常

一个英雄攻击另一个英雄的时候，如果发现另一个英雄已经挂了，就会抛出`EnemyHeroIsDeadException`
创建一个类`EnemyHeroIsDeadException`，并继承`Exception`
提供两个构造方法

1. 无参的构造方法
2. 带参的构造方法，并调用父类的对应的构造方法

```java
class EnemyHeroIsDeadException extends Exception{    
    public EnemyHeroIsDeadException(){
         
    }
    public EnemyHeroIsDeadException(String msg){
        super(msg);
    }
}
```

##### 抛出自定义异常

在`Hero`的`attack`方法中，当发现敌方英雄的血量为0的时候，抛出该异常

1. 创建一个`EnemyHeroIsDeadException`实例
2. 通过**throw** 抛出该异常
3.  当前方法通过 **throws** 抛出该异常

在外部调用attack方法的时候，就需要进行捕捉，并且捕捉的时候，可以通过`e.getMessage()` 获取当时出错的具体原因

```java
public class Hero {
    public String name;
    protected float hp;
 
    public void attackHero(Hero h) throws EnemyHeroIsDeadException{
        if(h.hp == 0){
            throw new EnemyHeroIsDeadException(h.name + " 已经挂了,不需要施放技能" );
        }
    }
    public String toString(){
        return name;
    }
    class EnemyHeroIsDeadException extends Exception{
        public EnemyHeroIsDeadException(){
             
        }
        public EnemyHeroIsDeadException(String msg){
            super(msg); //Exception的一个构造方法，参数是打印时信息，e.getMessage()可得到
        }
    }
      
    public static void main(String[] args) {  
        Hero garen =  new Hero();
        garen.name = "盖伦";
        garen.hp = 616;
 
        Hero teemo =  new Hero();
        teemo.name = "提莫";
        teemo.hp = 0;
         
        try {
            garen.attackHero(teemo);
             
        } catch (EnemyHeroIsDeadException e) {
            // TODO Auto-generated catch block
            System.out.println("异常的具体原因:"+e.getMessage());
            e.printStackTrace();
        }        
    }
}
```

#### 带资源的try语句

```java

try(Resource res = xxx)//可指定多个资源
{
     work with res
}             
```

在没有这个语法之前,流操作一般是这样写的:

```java
InputStream is = null;
OutputStream os = null;
try {
	//...
} catch (IOException e) {
	//...
}finally{
	try {
		if(os!=null){
			os.close();
		}
		if(is!=null){
			is.close();
		}
	} catch (IOException e2) {
		//...
	}
}	
```

而现在你可以这样写:

```java
try(
	InputStream is = new FileInputStream("...");
	OutputStream os = new FileOutputStream("...");
){
	//...
}catch (IOException e) {
	//...
}
```

不用写一大堆`finally`来关闭资源,所有实现`Closeable`的类声明都可以写在里面,最常见于流操作,`socket`操作,新版的`httpclient`也可以;
需要注意的是,try()的括号中可以写多行声明,每个声明的变量类型都必须是Closeable的子类,用分号隔开.

把流定义在try()里,try,catch或者finally结束的时候，会自动关闭
这种编写代码的方式叫做 **try-with-resources**， 这是从JDK7开始支持的技术

所有的流，都实现了一个接口叫做 **`AutoCloseable`**，任何类实现了这个接口，都可以在try()中进行实例化。 并且在try, catch, finally结束的时候自动关闭，回收相关资源。















